<?xml version="1.0" ?>
<!-- =================================================================================== -->
<!-- |    This document was autogenerated by xacro from ffw_lg2_leader.urdf.xacro      | -->
<!-- |    EDITING THIS FILE BY HAND IS NOT RECOMMENDED                                 | -->
<!-- =================================================================================== -->
<robot name="ffw_lg2_leader">
  <link name="world"/>
  <joint name="joint" type="prismatic">
    <parent link="world"/>
    <child link="arm_base_link"/>
    <origin rpy="0 0 0" xyz="0 0 1.4316"/>
    <axis xyz="0 0 1"/>
    <limit effort="1000" lower="-0.5" upper="0.25" velocity="4.8"/>
    <dynamics damping="0.1"/>
  </joint>
  <link name="arm_base_link"/>
  <joint name="arm_l_joint1" type="revolute">
    <parent link="arm_base_link"/>
    <child link="arm_l_link1"/>
    <origin rpy="0 0 0" xyz="0 0.27 0"/>
    <axis xyz="0 1 0"/>
    <limit effort="1000" lower="-6.28" upper="6.28" velocity="4.8"/>
    <dynamics damping="0.1"/>
  </joint>
  <link name="arm_l_link1"/>
  <joint name="arm_l_joint2" type="revolute">
    <parent link="arm_l_link1"/>
    <child link="arm_l_link2"/>
    <origin rpy="0 0 0" xyz="0 0 0"/>
    <axis xyz="1 0 0"/>
    <limit effort="1000" lower="-6.28" upper="6.28" velocity="4.8"/>
    <dynamics damping="0.1"/>
  </joint>
  <link name="arm_l_link2"/>
  <joint name="arm_l_joint3" type="revolute">
    <parent link="arm_l_link2"/>
    <child link="arm_l_link3"/>
    <origin rpy="0 0 0" xyz="0 0 -0.3"/>
    <axis xyz="0 0 1"/>
    <limit effort="1000" lower="-6.28" upper="6.28" velocity="4.8"/>
    <dynamics damping="0.1"/>
  </joint>
  <link name="arm_l_link3"/>
  <joint name="arm_l_joint4" type="revolute">
    <parent link="arm_l_link3"/>
    <child link="arm_l_link4"/>
    <origin rpy="0 0 0" xyz="0 0 -0.05"/>
    <axis xyz="0 1 0"/>
    <limit effort="1000" lower="-6.28" upper="6.28" velocity="4.8"/>
    <dynamics damping="0.1"/>
  </joint>
  <link name="arm_l_link4"/>
  <joint name="arm_l_joint5" type="revolute">
    <parent link="arm_l_link4"/>
    <child link="arm_l_link5"/>
    <origin rpy="0 0 0" xyz="0 0 -0.19"/>
    <axis xyz="0 0 1"/>
    <limit effort="1000" lower="-6.28" upper="6.28" velocity="4.8"/>
    <dynamics damping="0.1"/>
  </joint>
  <link name="arm_l_link5"/>
  <joint name="arm_l_joint6" type="revolute">
    <parent link="arm_l_link5"/>
    <child link="arm_l_link6"/>
    <origin rpy="0 0 0" xyz="0 0 -0.045"/>
    <axis xyz="0 1 0"/>
    <limit effort="1000" lower="-6.28" upper="6.28" velocity="4.8"/>
    <dynamics damping="0.1"/>
  </joint>
  <link name="arm_l_link6"/>
  <joint name="arm_l_joint7" type="revolute">
    <parent link="arm_l_link6"/>
    <child link="arm_l_link7"/>
    <origin rpy="0 0 0" xyz="0 0 -0.055"/>
    <axis xyz="1 0 0"/>
    <limit effort="1000" lower="-6.28" upper="6.28" velocity="4.8"/>
    <dynamics damping="0.1"/>
  </joint>
  <link name="arm_l_link7"/>
  <joint name="arm_r_joint1" type="revolute">
    <parent link="arm_base_link"/>
    <child link="arm_r_link1"/>
    <origin rpy="0 0 0" xyz="0 0 0"/>
    <axis xyz="0 1 0"/>
    <limit effort="1000" lower="-6.28" upper="6.28" velocity="4.8"/>
    <dynamics damping="0.1"/>
  </joint>
  <link name="arm_r_link1"/>
  <joint name="arm_r_joint2" type="revolute">
    <parent link="arm_r_link1"/>
    <child link="arm_r_link2"/>
    <origin rpy="0 0 0" xyz="0 -0.27 0"/>
    <axis xyz="1 0 0"/>
    <limit effort="1000" lower="-6.28" upper="6.28" velocity="4.8"/>
    <dynamics damping="0.1"/>
  </joint>
  <link name="arm_r_link2"/>
  <joint name="arm_r_joint3" type="revolute">
    <parent link="arm_r_link2"/>
    <child link="arm_r_link3"/>
    <origin rpy="0 0 0" xyz="0 0 -0.3"/>
    <axis xyz="0 0 1"/>
    <limit effort="1000" lower="-6.28" upper="6.28" velocity="4.8"/>
    <dynamics damping="0.1"/>
  </joint>
  <link name="arm_r_link3"/>
  <joint name="arm_r_joint4" type="revolute">
    <parent link="arm_r_link3"/>
    <child link="arm_r_link4"/>
    <origin rpy="0 0 0" xyz="0 0 -0.05"/>
    <axis xyz="0 1 0"/>
    <limit effort="1000" lower="-6.28" upper="6.28" velocity="4.8"/>
    <dynamics damping="0.1"/>
  </joint>
  <link name="arm_r_link4"/>
  <joint name="arm_r_joint5" type="revolute">
    <parent link="arm_r_link4"/>
    <child link="arm_r_link5"/>
    <origin rpy="0 0 0" xyz="0 0 -0.19"/>
    <axis xyz="0 0 1"/>
    <limit effort="1000" lower="-6.28" upper="6.28" velocity="4.8"/>
    <dynamics damping="0.1"/>
  </joint>
  <link name="arm_r_link5"/>
  <joint name="arm_r_joint6" type="revolute">
    <parent link="arm_r_link5"/>
    <child link="arm_r_link6"/>
    <origin rpy="0 0 0" xyz="0 0 -0.045"/>
    <axis xyz="0 1 0"/>
    <limit effort="1000" lower="-6.28" upper="6.28" velocity="4.8"/>
    <dynamics damping="0.1"/>
  </joint>
  <link name="arm_r_link6"/>
  <joint name="arm_r_joint7" type="revolute">
    <parent link="arm_r_link6"/>
    <child link="arm_r_link7"/>
    <origin rpy="0 0 0" xyz="0 0 -0.055"/>
    <axis xyz="1 0 0"/>
    <limit effort="1000" lower="-6.28" upper="6.28" velocity="4.8"/>
    <dynamics damping="0.1"/>
  </joint>
  <link name="arm_r_link7"/>
  <joint name="gripper_l_joint1" type="fixed">
    <origin rpy="0 0 0" xyz="0 0 0"/>
    <parent link="arm_l_link7"/>
    <axis xyz="0 1 0"/>
    <child link="gripper_l_link1"/>
    <limit effort="1000" lower="-6.28" upper="6.28" velocity="6.5"/>
  </joint>
  <link name="gripper_l_link1"/>
  <joint name="gripper_r_joint1" type="fixed">
    <origin rpy="0 0 0" xyz="0 0 0"/>
    <parent link="arm_r_link7"/>
    <axis xyz="0 1 0"/>
    <child link="gripper_r_link1"/>
    <limit effort="1000" lower="-6.28" upper="6.28" velocity="6.5"/>
  </joint>
  <link name="gripper_r_link1"/>
</robot>
